Workbook

Sheet Economy
A1: Year | B1: Quarter | C1: Period | D1: GDPGrowthPct | E1: InflationPct | F1: InterestRatePct | G1: UnemploymentRate | H1: FuelPriceIndex
A2: 1 | B2: Q1 | C2: ="Y"&A2&B2 -> Y1Q1 | D2: 2.8 | E2: 3.6 | F2: 4.4 | G2: 4 | H2: 112
A3: 1 | B3: Q2 | C3: ="Y"&A3&B3 -> Y1Q2 | D3: 2.6 | E3: 3.4 | F3: 4.4 | G3: 4.1 | H3: 114
A4: 1 | B4: Q3 | C4: ="Y"&A4&B4 -> Y1Q3 | D4: 2.4 | E4: 3.2 | F4: 4.3 | G4: 4.1 | H4: 113
A5: 1 | B5: Q4 | C5: ="Y"&A5&B5 -> Y1Q4 | D5: 2.2 | E5: 3 | F5: 4.3 | G5: 4.2 | H5: 111
A6: 2 | B6: Q1 | C6: ="Y"&A6&B6 -> Y2Q1 | D6: 2 | E6: 2.8 | F6: 4.2 | G6: 4.2 | H6: 110
A7: 2 | B7: Q2 | C7: ="Y"&A7&B7 -> Y2Q2 | D7: 1.8 | E7: 2.7 | F7: 4.1 | G7: 4.3 | H7: 108
A8: 2 | B8: Q3 | C8: ="Y"&A8&B8 -> Y2Q3 | D8: 2.1 | E8: 2.6 | F8: 4 | G8: 4.2 | H8: 109
A9: 2 | B9: Q4 | C9: ="Y"&A9&B9 -> Y2Q4 | D9: 2.4 | E9: 2.5 | F9: 3.9 | G9: 4.1 | H9: 107

Sheet Consumer_Segments
A1: SegmentNo | B1: Segment | C1: PreferredVehicleClasses | D1: HotButtons
A2: 1 | B2: Value Seekers | C2: Economy, Truck | D2: Price, Economy
A3: 2 | B3: Families | C3: Family, Economy, Minivan | D3: Safety, Size, Quality
A4: 3 | B4: Singles | C4: Utility, Truck, Sports | D4: Styling, Performance
A5: 4 | B5: High Income | C5: Family, Luxury, Sports, Minivan | D5: Quality, Styling, Performance
A6: 5 | B6: Enterprisers | C6: Utility, Luxury | D6: Performance, Utility, Quality

Sheet Microsegments
A1: Microsegment | B1: SegmentNo | C1: Segment | D1: PreferredVehicleClass | E1: ClassCode
A2: 1E | B2: 1 | C2: Value Seekers | D2: Economy | E2: E
A3: 1T | B3: 1 | C3: Value Seekers | D3: Truck | E3: T
A4: 2F | B4: 2 | C4: Families | D4: Family | E4: F
A5: 2E | B5: 2 | C5: Families | D5: Economy | E5: E
A6: 2M | B6: 2 | C6: Families | D6: Minivan | E6: M
A7: 3U | B7: 3 | C7: Singles | D7: Utility | E7: U
A8: 3T | B8: 3 | C8: Singles | D8: Truck | E8: T
A9: 3S | B9: 3 | C9: Singles | D9: Sports | E9: S
A10: 4F | B10: 4 | C10: High Income | D10: Family | E10: F
A11: 4L | B11: 4 | C11: High Income | D11: Luxury | E11: L
A12: 4S | B12: 4 | C12: High Income | D12: Sports | E12: S
A13: 4M | B13: 4 | C13: High Income | D13: Minivan | E13: M
... A15: 5L | B15: 5 | C15: Enterprisers | D15: Luxury | E15: L

Sheet Market_Sales
A1: Year | B1: Quarter | C1: Microsegment | D1: Segment | E1: VehicleClass | F1: PredictedSales000s | G1: ActualSales000s | H1: MarketShare | J1: VehicleClass | K1: (All)
A2: 1 | B2: Q1 | C2: 1E | D2: Value Seekers | E2: Economy | F2: 150 | G2: 156 | H2: =G2/SUM($G$2:$G$15) -> 0.11403509
A3: 1 | B3: Q1 | C3: 1T | D3: Value Seekers | E3: Truck | F3: 82 | G3: 87 | H3: =G3/SUM($G$2:$G$15) -> 0.063596491 | J3: Sum of ActualSales000s | K3: Column Labels
A4: 1 | B4: Q1 | C4: 2F | D4: Families | E4: Family | F4: 230 | G4: 232 | H4: =G4/SUM($G$2:$G$15) -> 0.16959064 | J4: Row Labels | K4: Enterprisers | L4: Families | M4: High Income | N4: Singles | O4: Value Seekers | P4: Grand Total
A5: 1 | B5: Q1 | C5: 2E | D5: Families | E5: Economy | F5: 105 | G5: 111 | H5: =G5/SUM($G$2:$G$15) -> 0.081140351 | J5: 1 | K5: 657 | L5: 1866 | M5: 970 | N5: 1134 | O5: 957 | P5: 5584
A6: 1 | B6: Q1 | C6: 2M | D6: Families | E6: Minivan | F6: 112 | G6: 116 | H6: =G6/SUM($G$2:$G$15) -> 0.084795322 | J6: Q1 | K6: 157 | L6: 459 | M6: 232 | N6: 277 | O6: 243 | P6: 1368
A7: 1 | B7: Q1 | C7: 3U | D7: Singles | E7: Utility | F7: 118 | G7: 118 | H7: =G7/SUM($G$2:$G$15) -> 0.08625731 | J7: Q2 | K7: 169 | L7: 457 | M7: 245 | N7: 279 | O7: 239 | P7: 1389
A8: 1 | B8: Q1 | C8: 3T | D8: Singles | E8: Truck | F8: 84 | G8: 88 | H8: =G8/SUM($G$2:$G$15) -> 0.064327485 | J8: Q3 | K8: 170 | L8: 468 | M8: 244 | N8: 286 | O8: 234 | P8: 1402
A9: 1 | B9: Q1 | C9: 3S | D9: Singles | E9: Sports | F9: 74 | G9: 71 | H9: =G9/SUM($G$2:$G$15) -> 0.051900585 | J9: Q4 | K9: 161 | L9: 482 | M9: 249 | N9: 292 | O9: 241 | P9: 1425
A10: 1 | B10: Q1 | C10: 4F | D10: High Income | E10: Family | F10: 65 | G10: 63 | H10: =G10/SUM($G$2:$G$15) -> 0.046052632 | J10: 2 | K10: 717 | L10: 1994 | M10: 1057 | N10: 1230 | O10: 1017 | P10: 6015
A11: 1 | B11: Q1 | C11: 4L | D11: High Income | E11: Luxury | F11: 76 | G11: 73 | H11: =G11/SUM($G$2:$G$15) -> 0.053362573 | J11: Q1 | K11: 172 | L11: 489 | M11: 258 | N11: 295 | O11: 253 | P11: 1467
A12: 1 | B12: Q1 | C12: 4S | D12: High Income | E12: Sports | F12: 56 | G12: 54 | H12: =G12/SUM($G$2:$G$15) -> 0.039473684 | J12: Q2 | K12: 180 | L12: 492 | M12: 256 | N12: 301 | O12: 247 | P12: 1476
A13: 1 | B13: Q1 | C13: 4M | D13: High Income | E13: Minivan | F13: 42 | G13: 42 | H13: =G13/SUM($G$2:$G$15) -> 0.030701754 | J13: Q3 | K13: 185 | L13: 500 | M13: 271 | N13: 312 | O13: 260 | P13: 1528
A14: 1 | B14: Q1 | C14: 5U | D14: Enterprisers | E14: Utility | F14: 96 | G14: 92 | H14: =G14/SUM($G$2:$G$15) -> 0.067251462 | J14: Q4 | K14: 180 | L14: 513 | M14: 272 | N14: 322 | O14: 257 | P14: 1544
A15: 1 | B15: Q1 | C15: 5L | D15: Enterprisers | E15: Luxury | F15: 64 | G15: 65 | H15: =G15/SUM($G$2:$G$15) -> 0.04751462 | J15: Grand Total | K15: 1374 | L15: 3860 | M15: 2027 | N15: 2364 | O15: 1974 | P15: 11599
A16: 1 | B16: Q2 | C16: 1E | D16: Value Seekers | E16: Economy | F16: 153 | G16: 152 | H16: =G16/SUM($G$16:$G$29) -> 0.10943125
A17: 1 | B17: Q2 | C17: 1T | D17: Value Seekers | E17: Truck | F17: 83 | G17: 87 | H17: =G17/SUM($G$16:$G$29) -> 0.062634989
A18: 1 | B18: Q2 | C18: 2F | D18: Families | E18: Family | F18: 234 | G18: 240 | H18: =G18/SUM($G$16:$G$29) -> 0.17278618
A19: 1 | B19: Q2 | C19: 2E | D19: Families | E19: Economy | F19: 107 | G19: 101 | H19: =G19/SUM($G$16:$G$29) -> 0.072714183
A20: 1 | B20: Q2 | C20: 2M | D20: Families | E20: Minivan | F20: 114 | G20: 116 | H20: =G20/SUM($G$16:$G$29) -> 0.083513319
A21: 1 | B21: Q2 | C21: 3U | D21: Singles | E21: Utility | F21: 120 | G21: 115 | H21: =G21/SUM($G$16:$G$29) -> 0.082793377
A22: 1 | B22: Q2 | C22: 3T | D22: Singles | E22: Truck | F22: 86 | G22: 86 | H22: =G22/SUM($G$16:$G$29) -> 0.061915047
A23: 1 | B23: Q2 | C23: 3S | D23: Singles | E23: Sports | F23: 75 | G23: 78 | H23: =G23/SUM($G$16:$G$29) -> 0.056155508
A24: 1 | B24: Q2 | C24: 4F | D24: High Income | E24: Family | F24: 66 | G24: 67 | H24: =G24/SUM($G$16:$G$29) -> 0.048236141
A25: 1 | B25: Q2 | C25: 4L | D25: High Income | E25: Luxury | F25: 77 | G25: 77 | H25: =G25/SUM($G$16:$G$29) -> 0.055435565
A26: 1 | B26: Q2 | C26: 4S | D26: High Income | E26: Sports | F26: 57 | G26: 58 | H26: =G26/SUM($G$16:$G$29) -> 0.041756659
A27: 1 | B27: Q2 | C27: 4M | D27: High Income | E27: Minivan | F27: 43 | G27: 43 | H27: =G27/SUM($G$16:$G$29) -> 0.030957523
... A29: 1 | B29: Q2 | C29: 5L | D29: Enterprisers | E29: Luxury | F29: 65 | G29: 66 | H29: =G29/SUM($G$16:$G$29) -> 0.047516199
A30: 1 | B30: Q3 | C30: 1E | D30: Value Seekers | E30: Economy | F30: 155 | G30: 150 | H30: =G30/SUM($G$30:$G$43) -> 0.10699001
A31: 1 | B31: Q3 | C31: 1T | D31: Value Seekers | E31: Truck | F31: 85 | G31: 84 | H31: =G31/SUM($G$30:$G$43) -> 0.059914408
A32: 1 | B32: Q3 | C32: 2F | D32: Families | E32: Family | F32: 238 | G32: 243 | H32: =G32/SUM($G$30:$G$43) -> 0.17332382
A33: 1 | B33: Q3 | C33: 2E | D33: Families | E33: Economy | F33: 109 | G33: 115 | H33: =G33/SUM($G$30:$G$43) -> 0.082025678
A34: 1 | B34: Q3 | C34: 2M | D34: Families | E34: Minivan | F34: 116 | G34: 110 | H34: =G34/SUM($G$30:$G$43) -> 0.078459344
A35: 1 | B35: Q3 | C35: 3U | D35: Singles | E35: Utility | F35: 122 | G35: 120 | H35: =G35/SUM($G$30:$G$43) -> 0.085592011
A36: 1 | B36: Q3 | C36: 3T | D36: Singles | E36: Truck | F36: 87 | G36: 92 | H36: =G36/SUM($G$30:$G$43) -> 0.065620542
A37: 1 | B37: Q3 | C37: 3S | D37: Singles | E37: Sports | F37: 77 | G37: 74 | H37: =G37/SUM($G$30:$G$43) -> 0.05278174
A38: 1 | B38: Q3 | C38: 4F | D38: High Income | E38: Family | F38: 67 | G38: 69 | H38: =G38/SUM($G$30:$G$43) -> 0.049215407
A39: 1 | B39: Q3 | C39: 4L | D39: High Income | E39: Luxury | F39: 79 | G39: 76 | H39: =G39/SUM($G$30:$G$43) -> 0.054208274
A40: 1 | B40: Q3 | C40: 4S | D40: High Income | E40: Sports | F40: 58 | G40: 57 | H40: =G40/SUM($G$30:$G$43) -> 0.040656205
A41: 1 | B41: Q3 | C41: 4M | D41: High Income | E41: Minivan | F41: 44 | G41: 42 | H41: =G41/SUM($G$30:$G$43) -> 0.029957204
...

Sheet Microsegment_Sales
A1: Year | B1: Quarter | C1: Period | D1: Microsegment | E1: Segment | F1: VehicleClass | G1: Firm | H1: Product | I1: MicrosegmentShare | J1: UnitSales000s
A2: 1 | B2: Q1 | C2: ="Y"&A2&B2 -> Y1Q1 | D2: 1E | E2: Value Seekers | F2: Economy | G2: Firm D | H2: Delite | I2: 0.4288 | J2: 67
A3: 1 | B3: Q1 | C3: ="Y"&A3&B3 -> Y1Q1 | D3: 1E | E3: Value Seekers | F3: Economy | G3: Firm E | H3: Econo | I3: 0.2664 | J3: 42
A4: 1 | B4: Q1 | C4: ="Y"&A4&B4 -> Y1Q1 | D4: 1E | E4: Value Seekers | F4: Economy | G4: Firm A | H4: Alec | I4: 0.1755 | J4: 27
A5: 1 | B5: Q1 | C5: ="Y"&A5&B5 -> Y1Q1 | D5: 1E | E5: Value Seekers | F5: Economy | G5: Firm B | H5: Breeze | I5: 0.1293 | J5: 20
A6: 1 | B6: Q1 | C6: ="Y"&A6&B6 -> Y1Q1 | D6: 1T | E6: Value Seekers | F6: Truck | G6: Firm E | H6: Estruck | I6: 0.5616 | J6: 49
A7: 1 | B7: Q1 | C7: ="Y"&A7&B7 -> Y1Q1 | D7: 1T | E7: Value Seekers | F7: Truck | G7: Firm D | H7: Detonka | I7: 0.3407 | J7: 30
A8: 1 | B8: Q1 | C8: ="Y"&A8&B8 -> Y1Q1 | D8: 1T | E8: Value Seekers | F8: Truck | G8: Firm B | H8: Brute | I8: 0.0977 | J8: 8
A9: 1 | B9: Q1 | C9: ="Y"&A9&B9 -> Y1Q1 | D9: 2F | E9: Families | F9: Family | G9: Firm A | H9: Alfa | I9: 0.3617 | J9: 84
A10: 1 | B10: Q1 | C10: ="Y"&A10&B10 -> Y1Q1 | D10: 2F | E10: Families | F10: Family | G10: Firm C | H10: Cafav | I10: 0.2573 | J10: 60
A11: 1 | B11: Q1 | C11: ="Y"&A11&B11 -> Y1Q1 | D11: 2F | E11: Families | F11: Family | G11: Firm D | H11: Defy | I11: 0.1739 | J11: 40
A12: 1 | B12: Q1 | C12: ="Y"&A12&B12 -> Y1Q1 | D12: 2F | E12: Families | F12: Family | G12: Firm E | H12: Efizz | I12: 0.1365 | J12: 32
A13: 1 | B13: Q1 | C13: ="Y"&A13&B13 -> Y1Q1 | D13: 2F | E13: Families | F13: Family | G13: Firm B | H13: Boffo | I13: 0.0705 | J13: 16
... A401: 2 | B401: Q4 | C401: ="Y"&A401&B401 -> Y2Q4 | D401: 5L | E401: Enterprisers | F401: Luxury | G401: Firm D | H401: Dynamo | I401: 0.2147 | J401: 15

Sheet Vehicles
A1: Period_Index | B1: Period | C1: Year | D1: Quarter | E1: Firm | F1: Vehicle | G1: VehicleKey | H1: VehicleQuarter | I1: VehicleClass | J1: MSRP | K1: Size | L1: Horsepower | M1: Interior | N1: Styling | O1: Safety | P1: Quality
A2: =(C2-1)*4+VALUE(RIGHT(D2,1)) -> 1 | B2: Y1Q1 | C2: 1 | D2: Q1 | E2: Firm A | F2: Alec | G2: =E2&"_"&F2 -> Firm A_Alec | H2: =B2&"_"&G2 -> Y1Q1_Firm A_Alec | I2: Economy | J2: 15351 | K2: 14 | L2: 135 | M2: 2 | N2: 1 | O2: 3 | P2: 2
A3: =(C3-1)*4+VALUE(RIGHT(D3,1)) -> 1 | B3: Y1Q1 | C3: 1 | D3: Q1 | E3: Firm A | F3: Alfa | G3: =E3&"_"&F3 -> Firm A_Alfa | H3: =B3&"_"&G3 -> Y1Q1_Firm A_Alfa | I3: Family | J3: 24084 | K3: 28 | L3: 165 | M3: 2 | N3: 1 | O3: 3 | P3: 2
A4: =(C4-1)*4+VALUE(RIGHT(D4,1)) -> 1 | B4: Y1Q1 | C4: 1 | D4: Q1 | E4: Firm A | F4: Apex | G4: =E4&"_"&F4 -> Firm A_Apex | H4: =B4&"_"&G4 -> Y1Q1_Firm A_Apex | I4: Sports | J4: 31500 | K4: 48 | L4: 205 | M4: 3 | N4: 3 | O4: 2 | P4: 1
A5: =(C5-1)*4+VALUE(RIGHT(D5,1)) -> 1 | B5: Y1Q1 | C5: 1 | D5: Q1 | E5: Firm A | F5: Atlas | G5: =E5&"_"&F5 -> Firm A_Atlas | H5: =B5&"_"&G5 -> Y1Q1_Firm A_Atlas | I5: Minivan | J5: 26800 | K5: 78 | L5: 195 | M5: 2 | N5: 2 | O5: 3 | P5: 3
A6: =(C6-1)*4+VALUE(RIGHT(D6,1)) -> 1 | B6: Y1Q1 | C6: 1 | D6: Q1 | E6: Firm A | F6: Awesome | G6: =E6&"_"&F6 -> Firm A_Awesome | H6: =B6&"_"&G6 -> Y1Q1_Firm A_Awesome | I6: Utility | J6: 21149 | K6: 40 | L6: 220 | M6: 1 | N6: 1 | O6: 1 | P6: 2
A7: =(C7-1)*4+VALUE(RIGHT(D7,1)) -> 1 | B7: Y1Q1 | C7: 1 | D7: Q1 | E7: Firm B | F7: Beaut | G7: =E7&"_"&F7 -> Firm B_Beaut | H7: =B7&"_"&G7 -> Y1Q1_Firm B_Beaut | I7: Luxury | J7: 38385 | K7: 62 | L7: 240 | M7: 2 | N7: 4 | O7: 2 | P7: 2
A8: =(C8-1)*4+VALUE(RIGHT(D8,1)) -> 1 | B8: Y1Q1 | C8: 1 | D8: Q1 | E8: Firm B | F8: Boffo | G8: =E8&"_"&F8 -> Firm B_Boffo | H8: =B8&"_"&G8 -> Y1Q1_Firm B_Boffo | I8: Family | J8: 35003 | K8: 49 | L8: 200 | M8: 4 | N8: 3 | O8: 2 | P8: 2
A9: =(C9-1)*4+VALUE(RIGHT(D9,1)) -> 1 | B9: Y1Q1 | C9: 1 | D9: Q1 | E9: Firm B | F9: Breeze | G9: =E9&"_"&F9 -> Firm B_Breeze | H9: =B9&"_"&G9 -> Y1Q1_Firm B_Breeze | I9: Economy | J9: 16900 | K9: 18 | L9: 130 | M9: 2 | N9: 2 | O9: 2 | P9: 3
A10: =(C10-1)*4+VALUE(RIGHT(D10,1)) -> 1 | B10: Y1Q1 | C10: 1 | D10: Q1 | E10: Firm B | F10: Brute | G10: =E10&"_"&F10 -> Firm B_Brute | H10: =B10&"_"&G10 -> Y1Q1_Firm B_Brute | I10: Truck | J10: 24900 | K10: 72 | L10: 250 | M10: 2 | N10: 2 | O10: 2 | P10: 2
A11: =(C11-1)*4+VALUE(RIGHT(D11,1)) -> 1 | B11: Y1Q1 | C11: 1 | D11: Q1 | E11: Firm B | F11: Buzzy | G11: =E11&"_"&F11 -> Firm B_Buzzy | H11: =B11&"_"&G11 -> Y1Q1_Firm B_Buzzy | I11: Sports | J11: 34652 | K11: 54 | L11: 190 | M11: 3 | N11: 3 | O11: 2 | P11: 2
A12: =(C12-1)*4+VALUE(RIGHT(D12,1)) -> 1 | B12: Y1Q1 | C12: 1 | D12: Q1 | E12: Firm C | F12: Cafav | G12: =E12&"_"&F12 -> Firm C_Cafav | H12: =B12&"_"&G12 -> Y1Q1_Firm C_Cafav | I12: Family | J12: 31361 | K12: 49 | L12: 165 | M12: 4 | N12: 2 | O12: 2 | P12: 2
A13: =(C13-1)*4+VALUE(RIGHT(D13,1)) -> 1 | B13: Y1Q1 | C13: 1 | D13: Q1 | E13: Firm C | F13: Camini | G13: =E13&"_"&F13 -> Firm C_Camini | H13: =B13&"_"&G13 -> Y1Q1_Firm C_Camini | I13: Minivan | J13: 24144 | K13: 82 | L13: 200 | M13: 2 | N13: 1 | O13: 2 | P13: 1
... A201: =(C201-1)*4+VALUE(RIGHT(D201,1)) -> 8 | B201: Y1Q4 | C201: 2 | D201: Q4 | E201: Firm E | F201: Euro | G201: =E201&"_"&F201 -> Firm E_Euro | H201: =B201&"_"&G201 -> Y1Q4_Firm E_Euro | I201: Utility | J201: 26528 | K201: 59 | L201: 200 | M201: 1 | N201: 3 | O201: 1 | P201: 1

Sheet Data_model
A1: SourceTable | B1: SourceKey | C1: TargetTable | D1: TargetKey | E1: Relationship | F1: Notes | M1: =COUNTIFS($A$2:$A$201,A2,$B$2:$B$201,B2,$C$2:$C$201,C2,$D$2:$D$201,D2) -> 1
A2: DimQuarter | B2: Period | C2: FactVehicleQuarter | D2: Period | E2: 1:M
A3: DimVehicle | B3: VehicleKey | C3: FactVehicleQuarter | D3: VehicleKey | E3: 1:M
A4: DimQuarter | B4: Period | C4: FactMicrosegmentSales | D4: Period | E4: 1:M
A5: DimVehicle | B5: VehicleKey | C5: FactMicrosegmentSales | D5: VehicleKey | E5: 1:M
A6: DimMicrosegment | B6: MicrosegmentKey | C6: FactMicrosegmentSales | D6: MicrosegmentKey | E6: 1:M

Sheet External_Events
A1: EventID | B1: Year | C1: Quarter | D1: EventName | E1: AffectedArea | F1: ImpactDirection | G1: Description
A2: E01 | B2: 1 | C2: Q2 | D2: Fuel price increase | E2: Economy / Utility / Truck | F2: Mixed | G2: Higher fuel costs increase price sensitivity and support efficient vehicles.
A3: E02 | B3: 1 | C3: Q4 | D3: Consumer confidence improvement | E3: Market | F3: Positive | G3: Improved confidence supports vehicle sales.
A4: E03 | B4: 2 | C4: Q2 | D4: Financing conditions ease | E4: Market | F4: Positive | G4: Lower financing pressure supports higher-ticket purchases.
A5: E04 | B5: 2 | C5: Q3 | D5: Component supply pressure | E5: Manufacturing | F5: Negative | G5: Temporary component pressure increases lost-sales risk.

Sheet Market_LOOKUP
A1: MARKET LOOKUP
A3: Year | B3: 2
A4: Quarter | B4: Q2
A5: Firm | B5: Firm C
A6: Vehicle | B6: Cafav
A7: Microsegment | B7: 2F
A9: VEHICLE INFORMATION | D9: MARKET POSITION
A10: Vehicle Class | B10: {=_xlfn.XLOOKUP(1,(Vehicles!C:C=$B$3)*(Vehicles!D:D=$B$4)*(Vehicles!E:E=$B$5)*(Vehicles!F:F=$B$6),Vehicles!I:I)} -> Family | D10: Vehicle Demand | E10: {=_xlfn.XLOOKUP(1,(Market_Sales!A:A=$B$3)*(Market_Sales!B:B=$B$4)*(Market_Sales!C:C=$B$7),Market_Sales!G:G)} -> 257
A11: Starting MSRP | B11: {=_xlfn.XLOOKUP(1,(Vehicles!C:C=$B$3)*(Vehicles!D:D=$B$4)*(Vehicles!E:E=$B$5)*(Vehicles!F:F=$B$6),Vehicles!J:J)} -> 31361 | D11: Microsegment Share | E11: {=_xlfn.XLOOKUP(1,(Microsegment_Sales!A:A=$B$3)*(Microsegment_Sales!B:B=$B$4)*(Microsegment_Sales!D:D=$B$7),Microsegment_Sales!I:I)} -> 0.3667
A12: Size | B12: {=_xlfn.XLOOKUP(1,(Vehicles!C:C=$B$3)*(Vehicles!D:D=$B$4)*(Vehicles!E:E=$B$5)*(Vehicles!F:F=$B$6),Vehicles!K:K)} -> 49 | D12: Market Share | E12: {=_xlfn.XLOOKUP(1,(Market_Sales!A:A=$B$3)*(Market_Sales!B:B=$B$4)*(Market_Sales!C:C=$B$7),Market_Sales!H:H)} -> 0.17411924
A13: Horsepower | B13: {=_xlfn.XLOOKUP(1,(Vehicles!C:C=$B$3)*(Vehicles!D:D=$B$4)*(Vehicles!E:E=$B$5)*(Vehicles!F:F=$B$6),Vehicles!L:L)} -> 165 | D13: QoQ Demand Growth | E13: {=IFERROR(E10/_xlfn.XLOOKUP(1,(Market_Sales!A:A=IF(B4="Q1",B3-1,B3))*(Market_Sales!B:B=IF(B4="Q1","Q4","Q"&(VALUE(RIGHT(B4,1))-1)))*(Market_Sales!C:C=B7),Market_Sales!G:G)-1,"No Historical Data")} -> -0.011538462
A14: Interior | B14: {=_xlfn.XLOOKUP(1,(Vehicles!C:C=$B$3)*(Vehicles!D:D=$B$4)*(Vehicles!E:E=$B$5)*(Vehicles!F:F=$B$6),Vehicles!M:M)} -> 4 | D14: YoY Demand Growth | E14: {=IFERROR(E10/_xlfn.XLOOKUP(1,(Market_Sales!A:A=B3-1)*(Market_Sales!B:B=B4)*(Market_Sales!C:C=B7),Market_Sales!G:G)-1,"No Historical Data")} -> 0.070833333
A15: Styling | B15: {=_xlfn.XLOOKUP(1,(Vehicles!C:C=$B$3)*(Vehicles!D:D=$B$4)*(Vehicles!E:E=$B$5)*(Vehicles!F:F=$B$6),Vehicles!N:N)} -> 2
A16: Safety | B16: {=_xlfn.XLOOKUP(1,(Vehicles!C:C=$B$3)*(Vehicles!D:D=$B$4)*(Vehicles!E:E=$B$5)*(Vehicles!F:F=$B$6),Vehicles!O:O)} -> 2
A17: Quality | B17: {=_xlfn.XLOOKUP(1,(Vehicles!C:C=$B$3)*(Vehicles!D:D=$B$4)*(Vehicles!E:E=$B$5)*(Vehicles!F:F=$B$6),Vehicles!P:P)} -> 2
A19: ECONOMIC CONDITIONS
A20: GDP Growth | B20: {=_xlfn.XLOOKUP(1,(Economy!A:A=$B$3)*(Economy!B:B=$B$4),Economy!D:D)%} -> 0.018
A21: Inflation | B21: {=_xlfn.XLOOKUP(1,(Economy!A:A=$B$3)*(Economy!B:B=$B$4),Economy!D:D)%} -> 0.018
A22: Interest Rate | B22: {=_xlfn.XLOOKUP(1,(Economy!A:A=$B$3)*(Economy!B:B=$B$4),Economy!D:D)%} -> 0.018
A23: Unemployment Rate | B23: {=_xlfn.XLOOKUP(1,(Economy!A:A=$B$3)*(Economy!B:B=$B$4),Economy!D:D)%} -> 0.018
A24: Fuel Price | B24: {=_xlfn.XLOOKUP(1,(Economy!A:A=$B$3)*(Economy!B:B=$B$4),Economy!H:H)} -> 108

Sheet Market_Analysis
A1: MARKET DEMAND ANALYSIS | F1: VEHICLE PRICING ANALYSIS
A3: Microsegment | B3: Year 1 Demand | C3: Year 2 Demand | D3: YoY Growth | F3: Vehicle Class | G3: Market Avg MSRP | H3: Firm C MSRP | I3: Price Difference
A4: 1E | B4: =SUMIFS(Market_Sales!$G:$G,Market_Sales!$A:$A,1,Market_Sales!$C:$C,$A4) -> 615 | C4: =SUMIFS(Market_Sales!$G:$G,Market_Sales!$A:$A,2,Market_Sales!$C:$C, $A4) -> 663 | D4: =C4/B4-1 -> 0.07804878 | F4: Economy | G4: =AVERAGEIFS(Vehicles!$J:$J,Vehicles!$I:$I,$F4,Vehicles!$C:$C,2,Vehicles!$D:$D,"Q4") -> 14611 | H4: {=_xlfn.XLOOKUP(1,(Vehicles!$C$2:$C$1000=2)*(Vehicles!$D$2:$D$1000="Q4")*(Vehicles!$E$2:$E$1000="Firm C")*(Vehicles!$I$2:$I$1000=$F4),Vehicles!$J$2:$J$1000,"No Vehicle")} -> No Vehicle | I4: =IFERROR(H4/G4-1,"No Vehicle") -> No Vehicle
A5: 1T | B5: =SUMIFS(Market_Sales!$G:$G,Market_Sales!$A:$A,1,Market_Sales!$C:$C,$A5) -> 342 | C5: =SUMIFS(Market_Sales!$G:$G,Market_Sales!$A:$A,2,Market_Sales!$C:$C, $A5) -> 354 | D5: =C5/B5-1 -> 0.035087719 | F5: Family | G5: =AVERAGEIFS(Vehicles!$J:$J,Vehicles!$I:$I,$F5,Vehicles!$C:$C,2,Vehicles!$D:$D,"Q4") -> 27047.8 | H5: {=_xlfn.XLOOKUP(1,(Vehicles!$C$2:$C$1000=2)*(Vehicles!$D$2:$D$1000="Q4")*(Vehicles!$E$2:$E$1000="Firm C")*(Vehicles!$I$2:$I$1000=$F5),Vehicles!$J$2:$J$1000,"No Vehicle")} -> 31361 | I5: =IFERROR(H5/G5-1,"No Vehicle") -> 0.15946583
A6: 2F | B6: =SUMIFS(Market_Sales!$G:$G,Market_Sales!$A:$A,1,Market_Sales!$C:$C,$A6) -> 965 | C6: =SUMIFS(Market_Sales!$G:$G,Market_Sales!$A:$A,2,Market_Sales!$C:$C, $A6) -> 1053 | D6: =C6/B6-1 -> 0.09119171 | F6: Luxury | G6: =AVERAGEIFS(Vehicles!$J:$J,Vehicles!$I:$I,$F6,Vehicles!$C:$C,2,Vehicles!$D:$D,"Q4") -> 42094 | H6: {=_xlfn.XLOOKUP(1,(Vehicles!$C$2:$C$1000=2)*(Vehicles!$D$2:$D$1000="Q4")*(Vehicles!$E$2:$E$1000="Firm C")*(Vehicles!$I$2:$I$1000=$F6),Vehicles!$J$2:$J$1000,"No Vehicle")} -> 45997 | I6: =IFERROR(H6/G6-1,"No Vehicle") -> 0.092721053
A7: 2E | B7: =SUMIFS(Market_Sales!$G:$G,Market_Sales!$A:$A,1,Market_Sales!$C:$C,$A7) -> 439 | C7: =SUMIFS(Market_Sales!$G:$G,Market_Sales!$A:$A,2,Market_Sales!$C:$C, $A7) -> 449 | D7: =C7/B7-1 -> 0.022779043 | F7: Sports | G7: =AVERAGEIFS(Vehicles!$J:$J,Vehicles!$I:$I,$F7,Vehicles!$C:$C,2,Vehicles!$D:$D,"Q4") -> 33350.667 | H7: {=_xlfn.XLOOKUP(1,(Vehicles!$C$2:$C$1000=2)*(Vehicles!$D$2:$D$1000="Q4")*(Vehicles!$E$2:$E$1000="Firm C")*(Vehicles!$I$2:$I$1000=$F7),Vehicles!$J$2:$J$1000,"No Vehicle")} -> 33900 | I7: =IFERROR(H7/G7-1,"No Vehicle") -> 0.016471435
A8: 2M | B8: =SUMIFS(Market_Sales!$G:$G,Market_Sales!$A:$A,1,Market_Sales!$C:$C,$A8) -> 462 | C8: =SUMIFS(Market_Sales!$G:$G,Market_Sales!$A:$A,2,Market_Sales!$C:$C, $A8) -> 492 | D8: =C8/B8-1 -> 0.064935065 | F8: Utility | G8: =AVERAGEIFS(Vehicles!$J:$J,Vehicles!$I:$I,$F8,Vehicles!$C:$C,2,Vehicles!$D:$D,"Q4") -> 26119.25 | H8: {=_xlfn.XLOOKUP(1,(Vehicles!$C$2:$C$1000=2)*(Vehicles!$D$2:$D$1000="Q4")*(Vehicles!$E$2:$E$1000="Firm C")*(Vehicles!$I$2:$I$1000=$F8),Vehicles!$J$2:$J$1000,"No Vehicle")} -> 27900 | I8: =IFERROR(H8/G8-1,"No Vehicle") -> 0.068177685
A9: 3U | B9: =SUMIFS(Market_Sales!$G:$G,Market_Sales!$A:$A,1,Market_Sales!$C:$C,$A9) -> 476 | C9: =SUMIFS(Market_Sales!$G:$G,Market_Sales!$A:$A,2,Market_Sales!$C:$C, $A9) -> 522 | D9: =C9/B9-1 -> 0.096638655 | F9: Minivan | G9: =AVERAGEIFS(Vehicles!$J:$J,Vehicles!$I:$I,$F9,Vehicles!$C:$C,2,Vehicles!$D:$D,"Q4") -> 25614.667 | H9: {=_xlfn.XLOOKUP(1,(Vehicles!$C$2:$C$1000=2)*(Vehicles!$D$2:$D$1000="Q4")*(Vehicles!$E$2:$E$1000="Firm C")*(Vehicles!$I$2:$I$1000=$F9),Vehicles!$J$2:$J$1000,"No Vehicle")} -> 24144 | I9: =IFERROR(H9/G9-1,"No Vehicle") -> -0.057415023
A10: 3T | B10: =SUMIFS(Market_Sales!$G:$G,Market_Sales!$A:$A,1,Market_Sales!$C:$C,$A10) -> 352 | C10: =SUMIFS(Market_Sales!$G:$G,Market_Sales!$A:$A,2,Market_Sales!$C:$C, $A10) -> 379 | D10: =C10/B10-1 -> 0.076704545
A11: 3S | B11: =SUMIFS(Market_Sales!$G:$G,Market_Sales!$A:$A,1,Market_Sales!$C:$C,$A11) -> 306 | C11: =SUMIFS(Market_Sales!$G:$G,Market_Sales!$A:$A,2,Market_Sales!$C:$C, $A11) -> 329 | D11: =C11/B11-1 -> 0.075163399
A12: 4F | B12: =SUMIFS(Market_Sales!$G:$G,Market_Sales!$A:$A,1,Market_Sales!$C:$C,$A12) -> 270 | C12: =SUMIFS(Market_Sales!$G:$G,Market_Sales!$A:$A,2,Market_Sales!$C:$C, $A12) -> 289 | D12: =C12/B12-1 -> 0.07037037
A13: 4L | B13: =SUMIFS(Market_Sales!$G:$G,Market_Sales!$A:$A,1,Market_Sales!$C:$C,$A13) -> 301 | C13: =SUMIFS(Market_Sales!$G:$G,Market_Sales!$A:$A,2,Market_Sales!$C:$C, $A13) -> 338 | D13: =C13/B13-1 -> 0.12292359
A14: 4S | B14: =SUMIFS(Market_Sales!$G:$G,Market_Sales!$A:$A,1,Market_Sales!$C:$C,$A14) -> 228 | C14: =SUMIFS(Market_Sales!$G:$G,Market_Sales!$A:$A,2,Market_Sales!$C:$C, $A14) -> 250 | D14: =C14/B14-1 -> 0.096491228
A15: 4M | B15: =SUMIFS(Market_Sales!$G:$G,Market_Sales!$A:$A,1,Market_Sales!$C:$C,$A15) -> 171 | C15: =SUMIFS(Market_Sales!$G:$G,Market_Sales!$A:$A,2,Market_Sales!$C:$C, $A15) -> 180 | D15: =C15/B15-1 -> 0.052631579
A16: 5U | B16: =SUMIFS(Market_Sales!$G:$G,Market_Sales!$A:$A,1,Market_Sales!$C:$C,$A16) -> 392 | C16: =SUMIFS(Market_Sales!$G:$G,Market_Sales!$A:$A,2,Market_Sales!$C:$C, $A16) -> 435 | D16: =C16/B16-1 -> 0.10969388
A17: 5L | B17: =SUMIFS(Market_Sales!$G:$G,Market_Sales!$A:$A,1,Market_Sales!$C:$C,$A17) -> 265 | C17: =SUMIFS(Market_Sales!$G:$G,Market_Sales!$A:$A,2,Market_Sales!$C:$C, $A17) -> 282 | D17: =C17/B17-1 -> 0.064150943
A19: COMPETITOR ANALYSIS
A21: Vehicle Class | B21: Firm A | C21: Firm B | D21: Firm C | E21: Firm D | F21: Firm E
A22: Economy | B22: =COUNTIFS(Vehicles!$I:$I,$A22,Vehicles!$E:$E,B$21,Vehicles!$C:$C,2,Vehicles!$D:$D,"Q4") -> 1 | C22: =COUNTIFS(Vehicles!$I:$I,$A22,Vehicles!$E:$E,C$21,Vehicles!$C:$C,2,Vehicles!$D:$D,"Q4") -> 1 | D22: =COUNTIFS(Vehicles!$I:$I,$A22,Vehicles!$E:$E,D$21,Vehicles!$C:$C,2,Vehicles!$D:$D,"Q4") -> 0 | E22: =COUNTIFS(Vehicles!$I:$I,$A22,Vehicles!$E:$E,E$21,Vehicles!$C:$C,2,Vehicles!$D:$D,"Q4") -> 1 | F22: =COUNTIFS(Vehicles!$I:$I,$A22,Vehicles!$E:$E,F$21,Vehicles!$C:$C,2,Vehicles!$D:$D,"Q4") -> 1
A23: Family | B23: =COUNTIFS(Vehicles!$I:$I,$A23,Vehicles!$E:$E,B$21,Vehicles!$C:$C,2,Vehicles!$D:$D,"Q4") -> 1 | C23: =COUNTIFS(Vehicles!$I:$I,$A23,Vehicles!$E:$E,C$21,Vehicles!$C:$C,2,Vehicles!$D:$D,"Q4") -> 1 | D23: =COUNTIFS(Vehicles!$I:$I,$A23,Vehicles!$E:$E,D$21,Vehicles!$C:$C,2,Vehicles!$D:$D,"Q4") -> 1 | E23: =COUNTIFS(Vehicles!$I:$I,$A23,Vehicles!$E:$E,E$21,Vehicles!$C:$C,2,Vehicles!$D:$D,"Q4") -> 1 | F23: =COUNTIFS(Vehicles!$I:$I,$A23,Vehicles!$E:$E,F$21,Vehicles!$C:$C,2,Vehicles!$D:$D,"Q4") -> 1
A24: Luxury | B24: =COUNTIFS(Vehicles!$I:$I,$A24,Vehicles!$E:$E,B$21,Vehicles!$C:$C,2,Vehicles!$D:$D,"Q4") -> 0 | C24: =COUNTIFS(Vehicles!$I:$I,$A24,Vehicles!$E:$E,C$21,Vehicles!$C:$C,2,Vehicles!$D:$D,"Q4") -> 1 | D24: =COUNTIFS(Vehicles!$I:$I,$A24,Vehicles!$E:$E,D$21,Vehicles!$C:$C,2,Vehicles!$D:$D,"Q4") -> 1 | E24: =COUNTIFS(Vehicles!$I:$I,$A24,Vehicles!$E:$E,E$21,Vehicles!$C:$C,2,Vehicles!$D:$D,"Q4") -> 1 | F24: =COUNTIFS(Vehicles!$I:$I,$A24,Vehicles!$E:$E,F$21,Vehicles!$C:$C,2,Vehicles!$D:$D,"Q4") -> 0
A25: Sports | B25: =COUNTIFS(Vehicles!$I:$I,$A25,Vehicles!$E:$E,B$21,Vehicles!$C:$C,2,Vehicles!$D:$D,"Q4") -> 1 | C25: =COUNTIFS(Vehicles!$I:$I,$A25,Vehicles!$E:$E,C$21,Vehicles!$C:$C,2,Vehicles!$D:$D,"Q4") -> 1 | D25: =COUNTIFS(Vehicles!$I:$I,$A25,Vehicles!$E:$E,D$21,Vehicles!$C:$C,2,Vehicles!$D:$D,"Q4") -> 1 | E25: =COUNTIFS(Vehicles!$I:$I,$A25,Vehicles!$E:$E,E$21,Vehicles!$C:$C,2,Vehicles!$D:$D,"Q4") -> 0 | F25: =COUNTIFS(Vehicles!$I:$I,$A25,Vehicles!$E:$E,F$21,Vehicles!$C:$C,2,Vehicles!$D:$D,"Q4") -> 0
A26: Utility | B26: =COUNTIFS(Vehicles!$I:$I,$A26,Vehicles!$E:$E,B$21,Vehicles!$C:$C,2,Vehicles!$D:$D,"Q4") -> 1 | C26: =COUNTIFS(Vehicles!$I:$I,$A26,Vehicles!$E:$E,C$21,Vehicles!$C:$C,2,Vehicles!$D:$D,"Q4") -> 0 | D26: =COUNTIFS(Vehicles!$I:$I,$A26,Vehicles!$E:$E,D$21,Vehicles!$C:$C,2,Vehicles!$D:$D,"Q4") -> 1 | E26: =COUNTIFS(Vehicles!$I:$I,$A26,Vehicles!$E:$E,E$21,Vehicles!$C:$C,2,Vehicles!$D:$D,"Q4") -> 1 | F26: =COUNTIFS(Vehicles!$I:$I,$A26,Vehicles!$E:$E,F$21,Vehicles!$C:$C,2,Vehicles!$D:$D,"Q4") -> 1
A27: Minivan | B27: =COUNTIFS(Vehicles!$I:$I,$A27,Vehicles!$E:$E,B$21,Vehicles!$C:$C,2,Vehicles!$D:$D,"Q4") -> 1 | C27: =COUNTIFS(Vehicles!$I:$I,$A27,Vehicles!$E:$E,C$21,Vehicles!$C:$C,2,Vehicles!$D:$D,"Q4") -> 0 | D27: =COUNTIFS(Vehicles!$I:$I,$A27,Vehicles!$E:$E,D$21,Vehicles!$C:$C,2,Vehicles!$D:$D,"Q4") -> 1 | E27: =COUNTIFS(Vehicles!$I:$I,$A27,Vehicles!$E:$E,E$21,Vehicles!$C:$C,2,Vehicles!$D:$D,"Q4") -> 0 | F27: =COUNTIFS(Vehicles!$I:$I,$A27,Vehicles!$E:$E,F$21,Vehicles!$C:$C,2,Vehicles!$D:$D,"Q4") -> 1
A28: Total | B28: =SUM(B22:B27) -> 5 | C28: =SUM(C22:C27) -> 4 | D28: =SUM(D22:D27) -> 5 | E28: =SUM(E22:E27) -> 4 | F28: =SUM(F22:F27) -> 4
